Workbook
Name carrier_BioWet: Carrier!$A$3

Sheet README
A1: README
A3: Contact
A4: Baron Chen | B4: yi-chung.chen@empa.ch
A5: Robin Mutschler | B5: robin.mutschler@empa.ch
A7: Relevant datasets | B7: Description | C7: Link
A8: IEA | B8: ETP Clean Energy Technology Guide is an interactive framework that contains information for nearly 600 individual technology designs and components across the whole energy system | C8: ETP Clean Energy Technology Guide – Data Tools - IEA
A9: Danish Energy Agency | B9: Extensive and high quality technology descriptions | C9: https://ens.dk/en/analyses-and-statistics
A10: European Commission | B10: JRC-EU-TIMES Full model dataset | C10: https://data.jrc.ec.europa.eu/dataset/8141a398-41a8-42fa-81a4-5b825a51761b
A11: SWEET | B11: energy tech data | C11: https://sweet-cross.ch/data/energy-tech-parameters/2024-02-27/
A12: Preliminary work | B12: Preliminary classification & parameterization work by Robin & Cristina | C12: https://docs.google.com/presentation/d/1oeQVAHrxMZgUv_lBlpRWjX9dcrnxatpXH_WOpPOPivE/edit?usp=sharing
A13: Technology representation | B13: Preliminary work to define the boundary condition of a technology | C13: https://docs.google.com/presentation/d/1Js4_w0kzhL3zGCj_5YsGCvKfnxXCUHVAVOwmXP_sHO0/edit#slide=id.g24c4e5253f6_0_5
A14: Energieperspektiven BFE | B14: xkurs Negativemissionstechnologien und CCS | C14: https://www.bfe.admin.ch/bfe/fr/home/politik/energieperspektiven-2050-plus.exturl.html/aHR0cHM6Ly9wdWJkYi5iZmUuYWRtaW4uY2gvZGUvcHVibGljYX/Rpb24vZG93bmxvYWQvMTA2MjA=.html
A15: Energieperspektiven BFE | B15: Energieperspektiven alle Reports | C15: https://www.bfe.admin.ch/bfe/de/home/politik/energieperspektiven-2050-plus.html
A16: Energiestatistik BFE | B16: Energiestatistik BFE | C16: https://www.bfe.admin.ch/bfe/de/home/versorgung/statistik-und-geodaten/energiestatistiken/gesamtenergiestatistik.html
A17: VSE Studies | B17: Important reference for the Empa Swiss model | C17: https://www.strom.ch/de/energiezukunft-2050/download
A18: about database | B18: this Excel file is the collaborative document to contribute the data for reFuel.ch
B19: the cleaned data will be store in another format (e.g. csv, JSON)
A20: Energy-X path representation | B20: Empa's preliminary path representation | C20: https://miro.com/app/board/uXjVOAn1i64=/
A21: Previous VSE technology data collection | B21: The Google Sheet with previous VSE data | C21: https://docs.google.com/spreadsheets/d/1eQCuOR8Kq5_W_c7xZtdGj87lEK-D1_rSEdts_J6jZLs/edit?gid=369202019#gid=369202019
A23: FAIR principle:
A24: Findable
A25: Accessible
A26: Interoperable | B26: are the assumptions and definitions clear?
A27: Reusable | B27: Can the data be exported in other formats?
A28: NOTE | B28: seperate "data" and "information"
A30: Other guidelines
A31: Clear define each parameter and terminology and reference it
A32: Provide key info about the data (e.g. assumption, reference, boundary conditions…)
A33: Clean and structured data that can be read by the machine
A35: Adding reference
A36: if the reference do not have a DOI, you can upload a BibTex file, using following steps: 1. add reference in a reference management tool (e.g. Zetero) 2. select "Export item" with format "BibTex" 3. change the file name the same as reference ID in the Reference sheet. 4. upload the file to reFuel.ch WP3 teams folder (see link on the right) | B36: folder for BibTex files
A38: NOTE: | B38: download a copy of reference from report, in case it is not available later
A43: TODO [2026-01-23] | B43: align Ch4 and CH4
B44: clean the second column name in row 4 in ConvTech, remove 'unit'
B45: check the one_time_opex for in ConvTech
B46: do we really need 'main input', if the main input is always with ratio 1?

Sheet Metadata
A1: Sheet Name | B1: Column header | C1: Mapping header | D1: Unit / Format | E1: Description | F1: ehubX name | G1: Ontology IRI | H1: Note
A2: ConvTech | B2: ehubX Tech ID | C2: {=TRANSPOSE(OFFSET(ConvTech!F4,0,0,1,56))} -> ehubX Tech ID | D2: {=TRANSPOSE(OFFSET(ConvTech!F2,0,0,1,44))} -> [ehubX Tech ID] | E2: ehubX technology ID | F2: tech_id
C3: tech_id | D3: [Datapaper Tech ID] | E3: Internationalized Resource Identifier (IRI) of an ontology
A4: ConvTech | B4: Tech Ontology IRI | C4: Tech Ontology IRI | D4: [Ontology IRI] | E4: High level process type? TBD | H4: provide additional information about the process (e.g. SOFC, Alkaline, PEM…)
A5: ConvTech | B5: Process Type | C5: process_type | D5: [ProcessType] | E5: Description of the technology
A6: ConvTech | B6: Description | C6: description | D6: [str]
A7: ConvTech | B7: Main Sector | C7: unit_operation | D7: [str] | E7: The main sector (based on what?) of the technology, see "Predefined" sheet | H7: not clera what serctor/category/group refer to
A8: ConvTech | B8: Main Category | C8: main_sector | D8: [MainSector] | E8: The main category (based on what?) of the technology, see "Predefined" sheet
A9: ConvTech | B9: Category Specification | C9: main_category | D9: [MainCategory] | E9: Subcategory of the technology, based on technology details
A10: ConvTech | B10: Tech Type | C10: category_spec | D10: [CategorySpec] | E10: High-level technology type (based on what?) | H10: different then ehubX type
A11: ConvTech | B11: Reference Unit Size | C11: tech_type | D11: [TechType] | E11: The tech-econo data is based on this reference capacity (e.g.10 MW) | H11: one unit size, another for the unit of capacity (kW or kg/yr)?
A12: ConvTech | B12: Technology Year | C12: reference_unit_size | D12: [MWh/h] or [t/h] | E12: The year that the technology is available and the tech-econo data are based on
A13: ConvTech | B13: Cost Base | C13: cost_base_year | D13: [Year] | E13: The location/region that the cost parameters are based on (e.g. CH or Europe) | H13: specific for location?
A14: ConvTech | B14: Currency | C14: Cost Base | D14: [Location] | E14: The currency of the cost parameter | H14: move to economic?
A15: ConvTech | B15: Data Reference Year | C15: Currency | D15: [Currency] | E15: The year that the technology data are evaluated on (e.g. a technology is evaluted in 2020) | H15: change to 'Data Reference Year' to reflect that only cost but other data are evaluated
A16: ConvTech | B16: Technology Readiness Level | C16: Data Reference Year | D16: [Year] | E16: The technology readiness level, scale 1 to 9
A17: ConvTech | B17: Technology Maturity Evaluation | C17: trl_(1-9) | D17: [TRL 1-9] | E17: How maturity is a technology, see "Predefined" sheet | F17: trl
A18: ConvTech | B18: Technology Boundary | C18: tech_maturity | D18: [TechMaturity] | E18: The boundary of the technololgy (e.g. core componen, full system ready for operation?), TBD | H18: need to be defined?
A19: ConvTech | B19: Tech Drawing Added? | C19: tech_boundary | D19: [TechBoundary]
A20: ConvTech | B20: Overall Efficiency | C20: Tech Drawing Added? | D20: [boolean] | E20: The overall efficiency based on the specific inputs and outputs
A21: ConvTech | B21: Input, Output for Overall Efficiency | C21: overall_efficiency | D21: [0-1] | E21: The inputs and outputs for overall efficiency calculation
A22: ConvTech | B22: Input Carriers | C22: Input, Output for Overall Efficiency | D22: [Input Carrier, Output Carrier] | E22: The list of input carriers of the technology/process | F22: in_ecs
A23: ConvTech | B23: Main Input Carrier | C23: carriers_in | D23: [list of Carriers] | E23: In case multiple inputs are present, the main input has to be defined. The output efficiency is relative to the main input
A24: ConvTech | B24: Input Shares | C24: main_input | D24: [Carrier] | E24: The share of input energy/mass for each carrier | F24: in_ecs
A25: ConvTech | B25: Input Units | C25: Input Shares | D25: [list of floats, comma separated] | E25: The unit of the input shares
A26: ConvTech | B26: Output Carriers | C26: Input Units - Shares | D26: [list of units in kWh and kg] | E26: The list of output carriers of the technology/process | F26: out_ecs
A27: ConvTech | B27: Main Output Carrier | C27: ratios_in | D27: [list of float, comma separated] | E27: Relevant to dimension the plant / tech | F27: main_out_ec
A28: ConvTech | B28: Output Shares | C28: units_in | D28: [list of units, comma separated] | E28: The share of output energy/mass for each carrier | F28: out_ecs
A29: ConvTech | B29: Output Units | C29: carriers_out | D29: [list of Carriers] | E29: The unit of the output shares
A30: ConvTech | B30: Minimum Installation | C30: SwissX_carriers_out | D30: [list of Carriers] | E30: The minimumal installation capacity | F30: unit_cap_min
A31: ConvTech | B31: Economic Lifetime | C31: main_out | D31: [Carrier] | E31: The system lifetime for tech-econo assessment | F31: lifetime
A32: ConvTech | B32: CAPEX One Time | C32: ratios_out | D32: [list of float, comma separated] | E32: The fixed Capex independent from the capacity (e.g. project planning, adminstration...) | F32: one_time_capex
A33: ConvTech | B33: CAPEX Power Capacity | C33: SwissX_ratios_out | D33: [list of float, comma separated] | E33: The Capex depends on the capacity | F33: capex_per_cap
A34: ConvTech | B34: OPEX One Time | C34: units_out | D34: [list of units, comma separated] | E34: The fixed Opex independent from the capacity (e.g. license, management) | F34: one_time_opex | H34: is it one-time (CHF) or fixed (CHF/yr)?
A35: ConvTech | B35: OPEX Power Capacity as percentage of CAPEX | C35: Output Shares | D35: [list of float, comma separated] | E35: The percentage to estimate Opex based on the CAPEX (e.g. Opex CHF/yr is 4% of Capex)
A36: ConvTech | B36: OPEX Power Capacity | C36: Output Units - Shares | D36: [list of units, comma separated] | E36: The Opex based on the power capacity of the system | F36: opex_per_cap
A37: ConvTech | B37: OPEX Energy | C37: theoretical_efficiency | D37: [0-1] | E37: The Opex based on the annual energy production of the system | F37: opex_per_energy
A38: ConvTech | B38: Discount Rate | C38: operating_temperature_c | D38: °C | E38: The discoiunt rate to estimate the levelised costs of the technology | F38: interest_rate
A39: ConvTech | B39: Value Range Check | C39: min_installation_size | D39: kW, kg/hr | E39: If the technology has a value range
A40: ConvTech | B40: Uncertainty Rating | C40: lifetime_yr | D40: Years | E40: The rating of uncertainty level for tech-econo parameters
...

Sheet Predefined
A1: Sheet name | B1: Column header | C1: Values | D1: Description | E1: Ontology IRI | F1: Note
A2: ConvTech | B2: process_type | C2: Carbon Black Production
A3: ConvTech | B3: process_type | C3: CO2 capture
A4: ConvTech | B4: process_type | C4: CO2 transport
A5: ConvTech | B5: process_type | C5: Digestion
A6: ConvTech | B6: process_type | C6: Electricity production / Hydrogen use
A7: ConvTech | B7: process_type | C7: Electrochemical CO2 reduction
A8: ConvTech | B8: process_type | C8: Electrolysis
A9: ConvTech | B9: process_type | C9: Eletricity Transmission
A10: ConvTech | B10: process_type | C10: Fischer Tropsch
A11: ConvTech | B11: process_type | C11: Gas Boiler
A12: ConvTech | B12: process_type | C12: Gas Turbine
A13: ConvTech | B13: process_type | C13: Haberbosch
... A96: ConvTech | B96: lca_scenario | C96: SSP2-PkBudg1150_2050
A97: ConvTech | B97: tech_maturity | C97: Mature | F97: see Sheet "TechMaturity"
A98: ConvTech | B98: tech_maturity | C98: Emerging | F98: see Sheet "TechMaturity"
A99: ConvTech | B99: tech_maturity | C99: Prototype | F99: see Sheet "TechMaturity"
A100: ConvTech
A101: ConvTech
A102: ConvTech
A103: ConvTech
A104: ConvTech
A105: ConvTech
A106: ConvTech
A107: ConvTech
A108: ConvTech
A109: ConvTech
A110: ConvTech
A111: ConvTech
... A113: ConvTech

Sheet Unique values
A1: Sheet name | B1: ConvTech | C1: ConvTech | D1: ConvTech | E1: ConvTech | F1: ConvTech | G1: ConvTech | H1: ConvTech | I1: ConvTech | J1: ConvTech | K1: ConvTech
A2: Column header | B2: =ConvTech!I4 -> process_type | C2: =ConvTech!L4 -> main_sector | D2: =ConvTech!M4 -> main_category | E2: =ConvTech!N4 -> category_spec | F2: =ConvTech!O4 -> tech_type | G2: =ConvTech!R4 -> Cost Base | H2: =ConvTech!S4 -> Currency | I2: =ConvTech!V4 -> tech_maturity | J2: =ConvTech!W4 -> tech_boundary | K2: =ConvTech!BE4 -> lca_scenario
A3: Unique value count | B3: =COUNTA(B5:B1000) -> 28 | C3: =COUNTA(C5:C1000) -> 17 | D3: =COUNTA(D5:D1000) -> 22 | E3: =COUNTA(E5:E1000) -> 19 | F3: =COUNTA(F5:F1000) -> 2 | G3: =COUNTA(G5:G1000) -> 2 | H3: =COUNTA(H5:H1000) -> 2 | I3: =COUNTA(I5:I1000) -> 3 | ... K3: =COUNTA(K5:K1000) -> 5
A5: Unique values | B5: {=_xlfn.UNIQUE(_xlfn._xlws.FILTER(ConvTech!I5:I1066, (ConvTech!I5:I1066<>"")*(ConvTech!I5:I1066<>0)*(ConvTech!I5:I1066<>"na")))} -> CO2 capture | C5: {=_xlfn.UNIQUE(_xlfn._xlws.FILTER(ConvTech!L5:L1066, (ConvTech!L5:L1066<>"")*(ConvTech!L5:L1066<>0)*(ConvTech!L5:L1066<>"na")))} -> CO2 capture | D5: {=_xlfn.UNIQUE(_xlfn._xlws.FILTER(ConvTech!M5:M1066, (ConvTech!M5:M1066<>"")*(ConvTech!M5:M1066<>0)*(ConvTech!M5:M1066<>"na")))} -> Point source capture | E5: {=_xlfn.UNIQUE(_xlfn._xlws.FILTER(ConvTech!N5:N1066, (ConvTech!N5:N1066<>"")*(ConvTech!N5:N1066<>0)*(ConvTech!N5:N1066<>"na")))} -> Amine washing | F5: {=_xlfn.UNIQUE(_xlfn._xlws.FILTER(ConvTech!O5:O1066, (ConvTech!O5:O1066<>"")*(ConvTech!O5:O1066<>0)*(ConvTech!O5:O1066<>"na")))} -> Conversion | G5: {=_xlfn.UNIQUE(_xlfn._xlws.FILTER(ConvTech!R5:R1066, (ConvTech!R5:R1066<>"")*(ConvTech!R5:R1066<>0)*(ConvTech!R5:R1066<>"na")))} -> CH | H5: {=_xlfn.UNIQUE(_xlfn._xlws.FILTER(ConvTech!S5:S1066, (ConvTech!S5:S1066<>"")*(ConvTech!S5:S1066<>0)*(ConvTech!S5:S1066<>"na")))} -> CHF | I5: {=_xlfn.UNIQUE(_xlfn._xlws.FILTER(ConvTech!V5:V1066, (ConvTech!V5:V1066<>"")*(ConvTech!V5:V1066<>0)*(ConvTech!V5:V1066<>"na")))} -> Mature | J5: {=_xlfn.UNIQUE(_xlfn._xlws.FILTER(ConvTech!W5:W1066, (ConvTech!W5:W1066<>"")*(ConvTech!W5:W1066<>0)*(ConvTech!W5:W1066<>"na")))} -> Plant ready to operate | K5: {=_xlfn.UNIQUE(_xlfn._xlws.FILTER(ConvTech!BE5:BE1066, (ConvTech!BE5:BE1066<>"")*(ConvTech!BE5:BE1066<>0)*(ConvTech!BE5:BE1066<>"na")))} -> SSP2-PkBudg1000_2030
B6: Haberbosch | C6: Ammonia | D6: Pyrolysis | E6: Wet Biomass | F6: Transport | G6: CHF | H6: EUR | I6: Emerging | J6: Complete installation | K6: SSP2-PkBudg1000_2040
B7: Carbon black production | C7: Carbon Black | D7: DAC | E7: Adsorption | I7: Prototype | J7: FALSE | K7: SSP2-PkBudg1000_2050
B8: Gas Turbine | C8: Carbon Capture | D8: Digestion | E8: HPC cycling | K8: SSP2-PkBudg1000_2025
B9: Heat and Electricity generation | C9: Methane | D9: Fuelcell | E9: Waste
B10: Digestion | C10: Electricity / Hydrogen | D10: Grid / Hydrogen | E10: Methane
B11: Electricity production / Hydrogen use | C11: Thermal | D11: Building | E11: CO2 hydrogenation
B12: Gas Boiler | C12: CO2 transport | D12: Hydrogenation | E12: Transmission
B13: Heat generation | C13: Carbon Monoxide | D13: Pipeline | E13: Distribution
B14: Methane synthesis | C14: Electricity | D14: NonPipeline | E14: Thermal
B15: CO2 transport | C15: Methanol | D15: Electrochemical | E15: RWGS
B16: Electrochemical CO2 reduction | C16: Hydrogen / Electricity | D16: Grid | E16: Kerosine
B17: Eletricity Transmission | C17: Synfuels | D17: Process | E17: Gasoline
B18: Thermal Powerplant | C18: Hydro | D18: Hydrogen | E18: Mustrun Turbine
B19: Methanol production | C19: Syngas | D19: Thermochemical | E19: Oil
B20: Reverse water gas shift | C20: Hydrogen | D20: Electrolysis | E20: PV
B21: Hydrogen production / Electricity use | C21: Cement | D21: Hydrocarbons | E21: CO hydrogenation
B22: Fischer Tropsch | D22: Hydro | E22: Wind
B23: Thermochemical CO Hydrogenation | D23: Waste | E23: Wood
B24: Water turbine | D24: New Renewable
B25: Hydro | D25: Nuclear
B26: Solar | D26: Gasification
B27: Heat transfer
B28: Syngas production
B29: Hydrogen production
B30: Wind turbine
B31: SAF production (HEFA)
B32: Cement

Sheet Glossary
A1: Name | B1: Description
A2: LHV | B2: Low Heating Value
A3: HHV | B3: High Heating Value

Sheet Carrier
A1: Carrier Abbreviation | B1: Carrier description | C1: Carrier Type | D1: Carrier Category | E1: Base Carrier | F1: Color Code (HEX) | G1: Note | H1: Reference
A2: Biomass | B2: Woody & dry biomass | C2: Energy | D2: Bioenergy | E2: Biomass | G2: ehubX carrier
A3: BioWet | B3: Wet biomass | C3: Energy | D3: Bioenergy | E3: BioWet | G3: ehubX carrier
A4: Wood | B4: Energy Wood | C4: Energy | D4: Bioenergy | E4: Wood | G4: ehubX carrier
A5: WoodCh | B5: Energy Wood from Switzerland | C5: Energy | D5: Bioenergy | E5: Wood | G5: ehubX carrier
A6: WoodEu | B6: Energy Wood from Europe | C6: Energy | D6: Bioenergy | E6: Wood | G6: ehubX carrier
A7: El13 | B7: Electricity grid level 1 to 3 (Swissgrid definition of grid levels 380kV - 220kV) | C7: Energy | D7: Electricity | E7: El | G7: ehubX carrier | H7: https://www.swissgrid.ch/en/home/operation/power-grid/grid-levels.html
A8: ElDsr | B8: Electricity associated with Demand Side Response | C8: Energy | D8: Electricity | E8: El | G8: ehubX carrier
A9: El47 | B9: Electricity grid level 4 to 7 (Swissgrid definition of grid levels 1kV - 36kV) | C9: Energy | D9: Electricity | E9: El | G9: ehubX carrier | H9: https://www.swissgrid.ch/en/home/operation/power-grid/grid-levels.html
A10: ElBdg | B10: Behind the meter electricity in buildings | C10: Energy | D10: Electricity | E10: El | G10: ehubX carrier
A11: ElPvAlpin | B11: Electricity from alpine PV | C11: Energy | D11: Electricity | E11: El | G11: ehubX carrier
A12: ElRest | B12: Behind the meter electricity at non-residential buildings and sites | C12: Energy | D12: Electricity | E12: El | G12: ehubX carrier
A13: ElWind | B13: Electricity generated from wind turbines | C13: Energy | D13: Electricity | E13: El | G13: ehubX carrier
A14: ElExp | B14: Exported electricity (Grid level 1 to 3) | C14: Energy | D14: Electricity | E14: El | G14: ehubX carrier
A15: Ch4 | B15: Methane | C15: Energy | D15: Chemical fuel | E15: Ch4 | G15: ehubX carrier
A16: Ch4BioCh | B16: Biogas (Methane) sourced in CH | C16: Energy | D16: Chemical fuel | E16: Ch4 | G16: ehubX carrier
A17: Ch4SynEu | B17: Biogas (Methane) imported from the EU | C17: Energy | D17: Chemical fuel | E17: Ch4 | G17: ehubX carrier
A18: C8 | B18: Hydrocarbon fuels with 8 carbon atoms (representing gasoline) | C18: Energy | D18: Chemical fuel | E18: C8 | G18: ehubX carrier
A19: C12 | B19: Hydrocarbon fuel with 12 carbon atoms (representing diesel) | C19: Energy | D19: Chemical fuel | E19: C12 | G19: ehubX carrier
A20: C12Syn | B20: Hydrocarbon fuel with 12 carbon atoms (representing diesel). Synthesized. | C20: Energy | D20: Chemical fuel | E20: C12 | G20: ehubX carrier
A21: C12Av | B21: Hydrocarbon fuel with 12 carbon atoms (representing aviation fuels). | C21: Energy | D21: Chemical fuel | E21: C12 | G21: ehubX carrier
A22: CBio | B22: Biochar (Carbon from biomass) | C22: Material | E22: C | G22: ehubX carrier
A23: CO2 | B23: Carbon Dioxide | C23: Material | E23: CO2 | G23: ehubX carrier
A24: CO2Sys | B24: Carbon Dioxide as a ressource in the energy system | C24: Material | E24: CO2 | G24: ehubX carrier
A25: CO2Waste | B25: Carbon dioxide in the exhaust of waste incineration plants | C25: Material | E25: CO2 | G25: ehubX carrier
A26: CO2Wood | B26: Carbon dioxide in the exhaust of wood fired powerplants | C26: Material | E26: CO2 | G26: ehubX carrier
A27: CO2Exp | B27: Physically exported Carbon Dioxide | C27: Material | E27: CO2 | G27: ehubX carrier
A28: CO2Fluegas | B28: Carbon Dioxide from flue gas | C28: Material | E28: CO2
A29: O2 | B29: Oxygen | C29: Material | E29: O2 | G29: ehubX carrier
A30: H2 | B30: Hydrogen | C30: Energy | D30: Chemical fuel | E30: H2 | G30: ehubX carrier
A31: H2BlueEu | B31: Blue hydrogen (produced with carbon capture) imported from the EU | C31: Energy | D31: Chemical fuel | E31: H2 | G31: ehubX carrier
A32: H2GreenEu | B32: Green hydrogen (produced from renewables) imported from the EU | C32: Energy | D32: Chemical fuel | E32: H2 | G32: ehubX carrier
A33: H2Process | B33: Process Hydrogen (mixed with CO in syngas) | C33: Energy | D33: Chemical fuel | E33: H2 | G33: ehubX carrier
A34: HydroPumped | B34: Pumped Hydro | C34: Energy | E34: Hydro | G34: ehubX carrier
A35: HydroRor | B35: Run-of-River Hydro | C35: Energy | E35: Hydro | G35: ehubX carrier
A36: HydroS | B36: Hydro Storage | C36: Energy | E36: Hydro | G36: ehubX carrier
A37: HydroSMustrun | B37: Hydro Storage, Must-run fraction | C37: Energy | E37: Hydro | G37: ehubX carrier
A38: MeOH | B38: Methano | C38: Energy | E38: MeOH | G38: ehubX carrier
A39: Msw | B39: Municipal Solid Waste | C39: Energy | E39: Msw | G39: ehubX carrier
A40: MswPh | B40: Solid Waste Utilized for Process Heat | C40: Energy | E40: Msw | G40: ehubX carrier
...

Sheet Location
A1: Location Abbreviation | B1: Location Description | C1: Reference
A2: CH | B2: Switzerland
A3: ECA | B3: Europe and Central Asia | C3: https://ourworldindata.org/grapher/world-regions-according-to-the-world-bank
A4: NAC | B4: North America | C4: https://ourworldindata.org/grapher/world-regions-according-to-the-world-bank
A5: SAR | B5: South Asia | C5: https://ourworldindata.org/grapher/world-regions-according-to-the-world-bank
A6: MENA | B6: Middle East and North Africa | C6: https://ourworldindata.org/grapher/world-regions-according-to-the-world-bank
A7: SSA | B7: Sub-Saharan Africa | C7: https://ourworldindata.org/grapher/world-regions-according-to-the-world-bank
A8: EAP | B8: East Asia and Pacific | C8: https://ourworldindata.org/grapher/world-regions-according-to-the-world-bank

Sheet Currency
A1: Currency Name | B1: Currency Description | C1: Symbol | D1: Reference | E1: Assumption | F1: Note
A2: CHF | B2: Swiss franc | C2: Fr.
A3: USE | B3: United States dollar | C3: $
A4: EUR | B4: Euro | C4: €

Sheet Process
A1: Process ID | B1: Process Description | C1: Tech Type | D1: Process Category | E1: Primay Feedstock | F1: Feedstocks | G1: Products | H1: Reference | I1: Assumption
A2: electrolysis_water | B2: Electrolysis, water | C2: Conversion | D2: Electrolysis | E2: Hydrogen | F2: H2O, Electricity | G2: H2
A3: biomass_gasification_to_syngas | B3: Biomass gasification to syngas | C3: Conversion | D3: Gasification | E3: Syngas | F3: Wood, O2 | G3: H2
A4: msw_gasification_to_syngas | B4: Municipal solid waste gasification to syngas | C4: Conversion | D4: Gasification | E4: Syngas | F4: MSW | G4: H2
A5: wet_biomass_anaerobic_digestion_gas_separation | B5: Wet biomass anaerobic digestion with gas separation | C5: Conversion | D5: Digestion | E5: Methane | F5: BioWet | G5: CH4, CO2
A6: methane_synthesis_h2_co2_sabatier | B6: Methane synthesis from H2 and CO2 via the thermo catalytic Sabatier reaction | C6: Conversion | D6: Hydrogenation | E6: Methane | F6: H2, CO2 | G6: CH4, H2O, heat
A7: methane_synthesis_syngas_sabatier | B7: Methane synthesis from Syngas via the thermo catalytic Sabatier reaction | C7: Conversion | D7: Hydrogenation | E7: Methane | F7: H2, CO | G7: CH4, H2O, heat
A8: reverse_water_gas_shift_reaction | B8: Reverse water gas shift reaction plant | C8: Conversion | D8: Reverse Water Gas Shift Reaction | E8: CarbonMonoxide | F8: H2, CO2, heat | G8: CO
A9: methane_synthesis_biomass | B9: Biological methaniation | C9: Conversion | D9: Hydrogenation | E9: Methane | F9: H2, CO2 | G9: CH4, H2O, heat | H9: paper_müller_PowerX_2025
A10: methane_synthesis_archea | B10: Bioelectrochemical CO2 hydrogenation via methanogenic archea | C10: Conversion | D10: Hydrogenation | E10: Methane | F10: H2, CO2 | G10: CH4, H2O, heat | H10: paper_müller_PowerX_2025
A11: co2_direct_reaction | B11: CO2 reduction at electrode surface | C11: Conversion | D11: Hydrogenation | F11: CO2, H20, Electricity | G11: CO | H11: paper_müller_PowerX_2025
A12: co_electrolysis | B12: High temperature co-electrolysis of CO2 and H2O | C12: Conversion | D12: Electrolysis | E12: Co2 | F12: CO2, H2O, Electricity, heat | G12: CO, H2O, O2 | H12: paper_müller_PowerX_2025
A13: Elec_El13_El47 | B13: Electricity network between El13 and El47 | C13: Network | D13: Electricity Transport | G13: electricity
A14: Elec_El47_El13 | B14: Coupled electricity network between El47 and El13. | C14: Network | D14: Electricity Transport | G14: electricity
A15: Elec_El47_ElBdg | B15: Electricity network connection between El47 and buildings. | C15: Network | D15: Electricity Transport | G15: electricity
A16: Elec_ElBdg_El47 | B16: Coupled electricity network between buildings and El47. | C16: Network | D16: Electricity Transport | G16: electricity
A17: Elec_El47_ElRest | B17: Electricity network connection between El47 and other electricity nodes. | C17: Network | D17: Electricity Transport | G17: electricity
A18: Elec_ElRest_El47 | B18: Coupled electricity network between other electricity nodes and El47. | C18: Network | D18: Electricity Transport | G18: electricity
A19: Elec_Nuclear_U235_El13 | B19: Electricity generation from nuclear power (U235) at node El13. | C19: Conversion | D19: Fission | F19: U235 | G19: electricity
A20: Elec_Msw_Incinerator | B20: Electricity generation from municipal solid waste (MSW) incineration. | C20: Conversion | D20: Digestion | F20: Municipal solid waste | G20: electricity
A21: Elec_H2_Ccgt | B21: Hydrogen-fueled combined cycle gas turbine (CCGT) electricity generation). | C21: Conversion | D21: Electricity Generation | F21: H2 | G21: electricity
A22: Elec_H2_Ocgt | B22: Hydrogen-fueled open cycle gas turbine (OCGT) electricity generation. | C22: Conversion | D22: Electricity Generation | F22: H2 | G22: electricity
A23: Elec_Ch4_Chp | B23: Combined heat and power (CHP) generation using methane (CH₄). | C23: Conversion | D23: Electricity Generation | F23: CH4 | G23: heat, electricity
A24: Elec_Ch4_Ocgt | B24: Methane-fueled open cycle gas turbine (OCGT) electricity generation. | C24: Conversion | D24: Electricity Generation | F24: CH4 | G24: electricity
A25: Elec_Ch4_Ccgt | B25: Methane-fueled CCGT with carbon capture and storage (CCS). | C25: Conversion | D25: Electricity Generation | F25: CH4
A26: Elec_Ch4_CcgtCcs | B26: Methane-fueled CCGT with carbon capture and storage (CCS). | C26: Conversion | D26: Electricity Generation | F26: CH4
A27: Elec_Wood_Chp | B27: Combined heat and power (CHP) generation using wood. | C27: Conversion | D27: CHP Generation | F27: Wood | G27: heat, electricity
A28: Elec_Geothermal_Chp | B28: Geothermal-based CHP generation (2040). | C28: Conversion | D28: CHP Generation | F28: heat (geothermal) | G28: heat, electricity
A29: Elec_Fuelcell_El47 | B29: Electricity generation via fuel cells at node El47. | C29: Conversion | D29: Fuelcell
A30: Elec_FuelcellCh4_El47 | B30: Methane-fueled fuel cell electricity generation at El47. | C30: Conversion | D30: Fuelcell
A31: Hydro_HydroRor_Plant | B31: Run-of-river hydroelectric power plant. | C31: Conversion | D31: Hydropower | F31: H2O | G31: electricity
A32: Hydro_HydroS_Turbine | B32: Hydroelectric power generation from storage reservoirs. | C32: Conversion | D32: Hydropower | F32: H2O | G32: electricity
A33: Hydro_HydroSMustrun_Turbine | B33: Must-run hydroelectric power generation from storage reservoirs. | C33: Conversion | D33: Hydropower | F33: H2O | G33: electricity
A34: Hydro_HydroPumped_Turbine | B34: Pumped hydroelectric power generation (turbine mode). | C34: Conversion | D34: Hydropower | F34: H2O | G34: electricity
A35: Hydro_HydroPumped_Pump | B35: Pumped hydroelectric energy storage (pump mode). | C35: Conversion | D35: Hydropower | F35: H2O | G35: electricity
A36: Elec_Fuelcell_ElBdg | B36: Electricity generation via fuel cells in buildings (2030). | C36: Conversion | D36: Fuelcell | G36: electricity
A37: Elec_FuelcellCh4_ElBdg | B37: Methane-fueled fuel cell electricity generation in buildings (2030). | C37: Conversion | D37: Fuelcell | F37: CH4 | G37: heat
A38: Thermal_ThermalBdg_Hp | B38: Generic heat pump for residential heating, fixed COP 4 | C38: Conversion | D38: Heatpump | F38: heat | G38: heat
A39: Thermal_ThermalBdg_HpSc | B39: Coupled heat pump system for buildings. | C39: Conversion | D39: Heatpump | F39: heat
A40: Thermal_ThermalBdg_ElBdg_ThSc | B40: Electric heating system for buildings with thermal storage. | C40: Conversion | D40: Heating | F40: electricity
...

Sheet Process ID
A1: Processes Classification
A2: Process ID | B2: Process Description | C2: Tech Type | D2: Process Category | E2: Primay Feedstock | F2: Feedstocks | G2: Products | H2: Reference | I2: Assumption
A3: Ammonia_HaberBosch | B3: Synthesizing Ammonia from Haber Bosch Process | C3: Conversion | D3: Haber Bosch
A4: biomass_gasification_to_syngas | B4: Biomass gasification to syngas | C4: Conversion | D4: Gasification | E4: Syngas | F4: Wood, O2 | G4: H2
A5: CarbonCapture_Amine | B5: CO2 post combustion capture via Amine washing. Temperature swing process. 2030 reference based on an approx. 150 ktCO2/a plant size. | C5: Conversion | D5: Carbon Capture | F5: CO2, amine
A6: CarbonCapture_CO2Waste_Vent | B6: CO₂ venting from waste-related processes. | C6: Conversion | D6: Carbon Capture | F6: waste
A7: CarbonCapture_CO2Wood_Vent | B7: CO₂ venting from wood-related processes. | C7: Conversion | D7: Carbon Capture | F7: wood
A8: CarbonCapture_DacAds | B8: Direct air capture using adsorption technology. | C8: Conversion | D8: Carbon Capture | F8: air
A9: CarbonCapture_Hpc | B9: CO2 post combustion capture via Hot-Potassium Carbonate cycling. Pressure swing process. 2030 reference based on an approx. 150 ktCO2/a plant size. | C9: Conversion | D9: Carbon Capture | F9: CO2
A10: CarbonDioxide_CO2Sys_Vent | B10: Carbon dioxide venting from the CO₂ system. | C10: Conversion | D10: CO2 Venting | F10: CO2
A11: CarbonDioxide_Pipeline | B11: Not in Tech description | C11: Conversion | D11: Carbon Transport
A12: CarbonDioxide_RoadRail | B12: Not in Tech description | C12: Network | D12: CO2 Transport | G12: biochar
A13: CarbonMonoxide_CO_Vent | B13: Carbon monoxide venting. | C13: Conversion | D13: CO2 Venting
A14: CarbonMonoxide_ElecRR_CO2_CO | B14: Reverse water gas shift reaction plant. Mature technology, 2040. | C14: Conversion | D14: Reverse Water Gas Shift Reaction
A15: CarbonMonoxide_Rwgs_H2_CO | B15: Reverse water gas shift reaction plant. Emerging technology. | C15: Conversion | D15: Reverse Water Gas Shift Reaction
A16: co_electrolysis | B16: High temperature co-electrolysis of CO2 and H2O | C16: Conversion | D16: Electrolysis | E16: Co2 | F16: CO2, H2O, Electricity, heat | G16: CO, H2O, O2 | H16: paper_müller_PowerX_2025
A17: co2_direct_reaction | B17: CO2 reduction at electrode surface | C17: Conversion | D17: Hydrogenation | F17: CO2, H20, Electricity | G17: CO | H17: paper_müller_PowerX_2025
A18: Elec_Ch4_Ccgt | B18: Methane-fueled CCGT with carbon capture and storage (CCS). | C18: Conversion | D18: Electricity Generation | F18: CH4
A19: Elec_Ch4_CcgtCcs | B19: Methane-fueled CCGT with carbon capture and storage (CCS). | C19: Conversion | D19: Electricity Generation | F19: CH4
A20: Elec_Ch4_Chp | B20: Combined heat and power (CHP) generation using methane (CH₄). | C20: Conversion | D20: Electricity Generation | F20: CH4 | G20: heat, electricity
A21: Elec_Ch4_Ocgt | B21: Methane-fueled open cycle gas turbine (OCGT) electricity generation. | C21: Conversion | D21: Electricity Generation | F21: CH4 | G21: electricity
A22: Elec_El13_El47 | B22: Electricity network between El13 and El47 | C22: Network | D22: Electricity Transport | G22: electricity
A23: Elec_El47_El13 | B23: Coupled electricity network between El47 and El13. | C23: Network | D23: Electricity Transport | G23: electricity
A24: Elec_El47_ElBdg | B24: Electricity network connection between El47 and buildings. | C24: Network | D24: Electricity Transport | G24: electricity
A25: Elec_El47_ElRest | B25: Electricity network connection between El47 and other electricity nodes. | C25: Network | D25: Electricity Transport | G25: electricity
A26: Elec_ElBdg_El47 | B26: Coupled electricity network between buildings and El47. | C26: Network | D26: Electricity Transport | G26: electricity
A27: Elec_ElRest_El47 | B27: Coupled electricity network between other electricity nodes and El47. | C27: Network | D27: Electricity Transport | G27: electricity
A28: Elec_Fuelcell_El47 | B28: Electricity generation via fuel cells at node El47. | C28: Conversion | D28: Fuelcell
A29: Elec_Fuelcell_ElBdg | B29: Electricity generation via fuel cells in buildings (2030). | C29: Conversion | D29: Fuelcell | G29: electricity
A30: Elec_FuelcellCh4_El47 | B30: Methane-fueled fuel cell electricity generation at El47. | C30: Conversion | D30: Fuelcell
A31: Elec_FuelcellCh4_ElBdg | B31: Methane-fueled fuel cell electricity generation in buildings (2030). | C31: Conversion | D31: Fuelcell | F31: CH4 | G31: heat
A32: Elec_Geothermal_Chp | B32: Geothermal-based CHP generation (2040). | C32: Conversion | D32: CHP Generation | F32: heat (geothermal) | G32: heat, electricity
A33: Elec_H2_Ccgt | B33: Hydrogen-fueled combined cycle gas turbine (CCGT) electricity generation). | C33: Conversion | D33: Electricity Generation | F33: H2 | G33: electricity
A34: Elec_H2_Ocgt | B34: Hydrogen-fueled open cycle gas turbine (OCGT) electricity generation. | C34: Conversion | D34: Electricity Generation | F34: H2 | G34: electricity
A35: Elec_Msw_Incinerator | B35: Electricity generation from municipal solid waste (MSW) incineration. | C35: Conversion | D35: Digestion | F35: Municipal solid waste | G35: electricity
A36: Elec_Nuclear_U235_El13 | B36: Electricity generation from nuclear power (U235) at node El13. | C36: Conversion | D36: Fission | F36: U235 | G36: electricity
A37: Elec_Wood_Chp | B37: Combined heat and power (CHP) generation using wood. | C37: Conversion | D37: CHP Generation | F37: Wood | G37: heat, electricity
A38: electrolysis_water | B38: Electrolysis, water | C38: Conversion | D38: Electrolysis | E38: Hydrogen | F38: H2O, Electricity | G38: H2
A39: Hydro_HydroPumped_Pump | B39: Pumped hydroelectric energy storage (pump mode). | C39: Conversion | D39: Hydropower | F39: H2O | G39: electricity
A40: Hydro_HydroPumped_Turbine | B40: Pumped hydroelectric power generation (turbine mode). | C40: Conversion | D40: Hydropower | F40: H2O | G40: electricity
...

Sheet Technology ID
A1: Technology Classification
A2: [Sheet] | B2: [Datapaper Tech ID] | C2: [ehubX Tech ID] | D2: [Process ID] | E2: [Process Type] | F2: [str] | G2: [Ontology IRI] | H2: [str] | I2: [Tech Year] | J2: [MainSector] | K2: [MainCategory] | L2: [CategorySpec] | M2: [TechType]
A3: sheet | B3: tech_id | C3: ehubX Tech ID | D3: process_id | E3: process_type | F3: unit_operation | G3: tech_ontology_IRI | H3: description | I3: tech_year | J3: main_sector | K3: main_category | L3: category_spec | M3: tech_type
A4: ConvTech | B4: Ammonia_HaberBosch | C4: T_C_Conv_Ammonia_HaberBosch | D4: Ammonia_HaberBosch | E4: Ammonia Synthesis | F4: Haber Bosch unit | H4: Ammonia synthesis via Haber Bosch process. | I4: 2050 | J4: Ammonia | K4: Chemical Synthesis | L4: Haber Bosch | M4: Conversion
A5: ConvTech | B5: Ammonia_OCGT | C5: T_C_Conv_Ammonia_OCGT | D5: Ammonia_OCGT | E5: Electricity Generation | F5: OCGT | I5: 2050 | J5: Electricity | K5: Gas Turbine | L5: Ammonia fueled | M5: Conversion
A6: ConvTech | B6: Amine_Washing_CO2 | C6: T_C_Conv_CarbonCapture_Amine | D6: CarbonCapture_Amine | E6: CO2 Capture | F6: Amine washing unit | H6: CO2 post combustion capture via Amine washing. Temperature swing process. Reference based on an approx. 150 ktCO2/a plant size. | I6: 2030, 2040, 2050 | J6: Carbon Capture | K6: Point Source Capture | L6: Amine washing | M6: Conversion
A7: ConvTech | B7: Waste_Venting_CO2 | C7: T_C_Conv_CarbonCapture_CO2Waste_Vent | D7: CarbonCapture_CO2Waste_Vent | E7: CO2 Capture | F7: Ventilator | H7: CO2 venting from waste-related processes. | I7: 2050 | J7: Carbon Capture | K7: Ventilation | L7: Waste | M7: Conversion
A8: ConvTech | B8: Wood_Venting_CO2 | C8: T_C_Conv_CarbonCapture_CO2Wood_Vent | D8: CarbonCapture_CO2Wood_Vent | E8: CO2 Capture | F8: Ventilator | H8: CO2 venting from wood-related processes. | I8: 2050 | J8: Carbon Capture | K8: Ventilation | L8: Wood | M8: Conversion
A9: ConvTech | B9: CarbonCapture_Direct | C9: T_C_Conv_CarbonCapture_DacAds | D9: CarbonCapture_DacAds | E9: CO2 Capture | F9: DAC | H9: Direct air capture using adsorption technology. | I9: 2030, 2040, 2050 | J9: Carbon Capture | K9: DAC | L9: Adsorption | M9: Conversion
A10: ConvTech | B10: CarbonCapture_PressureSwing | C10: T_C_Conv_CarbonCapture_Hpc | D10: CarbonCapture_Hpc | E10: CO2 Capture | F10: Potassium Carbonate Cycling | H10: CO2 post combustion capture via Hot-Potassium Carbonate cycling. Pressure swing process. Reference based on an approx. 150 ktCO2/a plant size. | I10: 2030, 2040, 2050 | J10: Carbon Capture | K10: Point Source Capture | L10: HPC cycling | M10: Conversion
A11: ConvTech | B11: CO2_Venting | C11: T_C_Conv_CarbonDioxide_CO2Sys_Vent | D11: CarbonDioxide_CO2Sys_Vent | E11: CO2 Venting | F11: Ventilator | H11: Carbon dioxide venting from the CO2 system. | I11: na | J11: Carbon Dioxide | K11: Ventilation | L11: CO2 System | M11: Conversion
A12: ConvTech | B12: CO2_Pipeline | C12: T_C_Net_CarbonDioxide_Pipeline (T_C_Net_CarbonDioxide_CO2Sys_CO2Exp) | D12: CarbonDioxide_Pipeline | E12: CO2 Transport | F12: Pipeline | H12: Carbon Dioxide Pipeline | I12: 2050 | J12: Carbon Dioxide | K12: Pipeline | L12: General | M12: Transport
A13: ConvTech | B13: CO2_Roadrail | C13: T_C_Net_CarbonDioxide_RoadRail | D13: CarbonDioxide_RoadRail | E13: CO2 Transport | F13: Road, Rail | H13: Not in Tech description | I13: na | J13: Carbon Dioxide | K13: Road, Rail | L13: General | M13: Transport
A14: ConvTech | B14: CO_Venting | C14: T_C_Conv_CarbonMonoxide_CO_Vent | D14: CarbonMonoxide_CO_Vent | E14: CO Venting | F14: Venitlator | H14: Carbon monoxide venting. | I14: na | J14: Carbon Monoxide | K14: Ventilation | L14: General | M14: Conversion
A15: ConvTech | B15: CO2_RWGS_CO | C15: T_C_CarbonMonoxide_ElecRR_CO2 | D15: CarbonMonoxide_ElecRR_CO2 | E15: Electrochemical CO2 Reduction | F15: Electrolyzer | I15: na | J15: Carbon Monoxide | K15: Electrolysis | L15: Reduction | M15: Conversion
A16: ConvTech | B16: H2_CO2_RWGS_CO | C16: T_C_Conv_CarbonMonoxide_Rwgs_H2_CO | D16: CarbonMonoxide_Rwgs_H2_CO | E16: Reverse Water Gas Shift | F16: RWGS reactor | H16: Reverse water gas shift reaction plant. Emerging technology. | I16: 2030, 2040 | J16: Carbon Monoxide | K16: RWGS | L16: General | M16: Conversion
A17: ConvTech | B17: CH4_CCGT | C17: T_C_Conv_Elec_CH4_Ccgt | D17: Elec_CH4_Ccgt | E17: Electricity Generation | F17: CCGT | H17: Methane-fueled CCGT | I17: 2050 | J17: Electricity | K17: Gas Turbine | L17: Methane fueled | M17: Conversion
A18: ConvTech | B18: CH4_CCGT_CCS | C18: T_C_Conv_Elec_CH4_CCGT + CCS Combo | D18: Elec_CH4_CCGT + CCS Combo | E18: Electricity Generation | F18: CCGT, CCS | H18: Methane-fueled CCGT with carbon capture and storage (CCS). | I18: 2050 | J18: Electricity, Carbon Capture | K18: Gas Turbine, CCS | L18: Methane fueled | M18: Conversion
A19: ConvTech | B19: CH4_CHP | C19: T_C_Conv_Elec_CH4_Chp | D19: Elec_CH4_Chp | E19: CHP Generation | F19: Heat and power co-generation unit | H19: Combined heat and power (CHP) generation using methane (CH₄). | I19: 2050 | J19: Electricity, Heat | K19: CHP | L19: Methane fueled | M19: Conversion
A20: ConvTech | B20: CH4_OCGT | C20: T_C_Conv_Elec_CH4_Ocgt | D20: Elec_CH4_Ocgt | E20: Electricity Generation | F20: OCGT | H20: Methane-fueled open cycle gas turbine (OCGT) electricity generation. | I20: 2050 | J20: Electricity | K20: Gas Turbine | L20: Methane fueled | M20: Conversion
A21: ConvTech | B21: Electricity | C21: T_C_Net_Elec_El13_El47 | D21: Elec_El13_El47 | E21: Eletricity Transmission | F21: Transformer | H21: Not in Tech description | I21: 2020, 2030, 2040, 2050 | J21: Electricity | K21: Grid | L21: Transmission | M21: Transport
A22: ConvTech | B22: Electricity_Buildings | C22: T_C_Net_Elec_El47_ElBdg | D22: Elec_El47_ElBdg | E22: Eletricity Transmission | F22: Grid | H22: Electricity network connection between El47 and buildings. | I22: 2020, 2030, 2040, 2050 | J22: Electricity | K22: Grid | L22: Distribution | M22: Transport
A23: ConvTech | B23: Electricity_Node47_ToRest | C23: T_C_Net_Elec_El47_ElRest | D23: Elec_El47_ElRest | E23: Eletricity Transmission | F23: Grid | H23: Electricity network connection between El47 and other electricity nodes. | I23: 2020, 2030, 2040, 2050 | J23: Electricity | K23: Grid | L23: Distribution | M23: Transport
A24: ConvTech | B24: Coupled_Electricity_Buildings | C24: T_C_NetCoupled_Elec_ElBdg_El47 | D24: Elec_ElBdg_El47 | E24: Eletricity Transmission | F24: Grid | H24: Coupled electricity network between buildings and El47. | I24: 2020, 2050 | J24: Electricity | K24: Grid | L24: Distribution | M24: Transport
A25: ConvTech | B25: Coupled_Electricity_Node47_ToRest | C25: T_C_NetCoupled_Elec_ElRest_El47 | D25: Elec_ElRest_El47 | E25: Eletricity Transmission | F25: Grid | H25: Coupled electricity network between other electricity nodes and El47. | I25: 2020, 2050 | J25: Electricity | K25: Grid | L25: Distribution | M25: Transport
A26: ConvTech | B26: H2_Fuelcell_Buildings | C26: T_C_Conv_Elec_Fuelcell_ElBdg | D26: Elec_Fuelcell_ElBdg | E26: Electricity Generation | F26: Fuel cell | H26: Electricity generation via fuel cells in buildings. | I26: 2040, 2050 | J26: Electricity | K26: Fuel Cell | L26: Hydrogen fueled | M26: Conversion
A27: ConvTech | B27: H2_Fuelcell | C27: T_C_Conv_Elec_Fuelcell_H2_El47 | D27: Elec_Fuelcell_H2_El47 | E27: Electricity Generation | F27: Fuel cell | H27: Electricity generation via fuel cells at node El47. | I27: 2040, 2050 | J27: Electricity | K27: Fuel Cell | L27: Hydrogen fueled | M27: Conversion
A28: ConvTech | B28: CH4_Fuelcell | C28: T_C_Conv_Elec_FuelcellCH4_El47 | D28: Elec_FuelcellCH4_El47 | E28: Electricity Generation | F28: Fuel cell | H28: Methane-fueled fuel cell electricity generation at El47. | I28: 2030 | J28: Electricity | K28: Fuel Cell | L28: Methane fueled | M28: Conversion
A29: ConvTech | B29: CH4_Fuelcell_Buildings | C29: T_C_Conv_Elec_FuelcellCH4_ElBdg | D29: Elec_FuelcellCH4_ElBdg | E29: Electricity Generation | F29: Fuel cell | H29: Methane-fueled fuel cell electricity generation in buildings. | I29: 2030 | J29: Electricity | K29: Fuel Cell | L29: Methane fueled | M29: Conversion
A30: ConvTech | B30: Geothermal_CHP | C30: T_C_Conv_Elec_Geothermal_Chp | D30: Elec_Geothermal_Chp | E30: CHP Generation | F30: Geothermal power plant | H30: Geothermal-based CHP generation. | I30: 2050 | J30: Electricity, Heat | K30: Geothermal | L30: General | M30: Conversion
A31: ConvTech | B31: H2_CCGT | C31: T_C_Conv_Elec_H2_Ccgt | D31: Elec_H2_Ccgt | E31: Electricity Generation | F31: CCGT | H31: Hydrogen-fueled combined cycle gas turbine (CCGT) electricity generation. | I31: 2050 | J31: Electricity | K31: Gas Turbine | L31: Hydrogen fueled | M31: Conversion
A32: ConvTech | B32: H2_OCGT | C32: T_C_Conv_Elec_H2_Ocgt | D32: Elec_H2_Ocgt | E32: Electricity Generation | F32: OCGT | H32: Hydrogen-fueled open cycle gas turbine (OCGT) electricity generation. | I32: 2050 | J32: Electricity | K32: Gas Turbine | L32: Hydrogen fueled | M32: Conversion
A33: ConvTech | B33: MunicipalSolidWaste_Incinerator_Electricity | C33: T_C_Conv_Elec_Msw_Incinerator | D33: Elec_Msw_Incinerator | E33: Thermal Powerplant | F33: Incineration Plant | H33: Electricity generation from municipal solid waste (MSW) incineration. | I33: 2020, 2030, 2040, 2050 | J33: Electricity | K33: Incinerator | L33: Waste | M33: Conversion
A34: ConvTech | B34: U235_NuclearReactor_Electricity | C34: T_C_Conv_Elec_Nuclear_U235_El13 | D34: Elec_Nuclear_U235_El13 | E34: Electricity Generation | F34: Nuclear power Plant | G34: http://openenergy-platform.org/ontology/oeo/OEO_00020053 | H34: Electricity generation from nuclear power (U235) at node El13. | I34: 2050 | J34: Electricity | K34: Nuclear | L34: U235 | M34: Conversion
A35: ConvTech | B35: Wood_CHP | C35: T_C_Conv_Elec_Wood_Chp | D35: Elec_Wood_Chp | E35: CHP Generation | F35: Heat and power co-generation unit | H35: Combined heat and power (CHP) generation using wood. | I35: 2020, 2030, 2040, 2050 | J35: Electricity, Heat | K35: CHP | L35: Wood | M35: Conversion
A36: ConvTech | B36: Hydro_Pumped_Pump | C36: T_C_Conv_Hydro_HydroPumped_Pump | D36: Hydro_HydroPumped_Pump | E36: Electricity Generation | F36: Hydropower Plant | H36: Pumped hydroelectric energy storage (pump mode). | I36: 2020, 2030, 2040, 2050 | J36: Electricity | K36: Hydro | L36: Pumped | M36: Conversion
A37: ConvTech | B37: Hydro_Pumped_Turbine | C37: T_C_Conv_Hydro_HydroPumped_Turbine | D37: Hydro_HydroPumped_Turbine | E37: Electricity Generation | F37: Hydropower Plant | H37: Pumped hydroelectric power generation (turbine mode). | I37: 2020, 2030, 2040, 2050 | J37: Electricity | K37: Hydro | L37: Pumped | M37: Conversion
A38: ConvTech | B38: Hydro_Run-of-river | C38: T_C_Conv_Hydro_HydroRor_Plant | D38: Hydro_HydroRor_Plant | E38: Electricity Generation | F38: Hydropower Plant | H38: Run-of-river hydroelectric power plant. | I38: 2020, 2030, 2040, 2050 | J38: Electricity | K38: Hydro | L38: Run-of-river | M38: Conversion
A39: ConvTech | B39: Hydro_Storage_Turbine | C39: T_C_Conv_Hydro_HydroS_Turbine | D39: Hydro_HydroS_Turbine | E39: Electricity Generation | F39: Hydropower Plant | H39: Hydroelectric power generation from storage reservoirs. | I39: 2020, 2030, 2040, 2050 | J39: Electricity | K39: Hydro | L39: Storage resevoirs | M39: Conversion
A40: ConvTech | B40: Hydro_Storage_Must-run_Turbine | C40: T_C_Conv_Hydro_HydroSMustrun_Turbine | D40: Hydro_HydroSMustrun_Turbine | E40: Electricity Generation | F40: Hydropower Plant | H40: Must-run hydroelectric power generation from storage reservoirs. | I40: 2020, 2050 | J40: Electricity | K40: Hydro | L40: Mustrun Turbine | M40: Conversion
...

Sheet LCA ID
A1: LCA Classification
A2: [ehubX Tech ID] | B2: [LCA ID] | C2: [Reference product] | D2: [LCA unit] | E2: [Location] | J2: [LCA Scenario]
A3: ehubX tech ID | B3: lca_id | C3: ref_product | D3: lca_unit | E3: Location | F3: SSP2-NDC_2025 | G3: SSP2-NDC_2030 | H3: SSP2-NDC_2040 | I3: SSP2-NDC_2050 | J3: SSP2-PkBudg1000_2025 | K3: SSP2-PkBudg1000_2030 | L3: SSP2-PkBudg1000_2040 | M3: SSP2-PkBudg1000_2050
A4: T_C_CarbonMonoxide_ElecRR_CO2_CO | B4: electrolyzer production, 1MWe, SOEC, Stack | C4: electrolyzer, 1MWe, SOEC, Stack | D4: kgCO2eq/kW | E4: RER | F4: 71.799597 | G4: 49.732848 | H4: 34.110871 | I4: 25.663843 | J4: 71.796199 | K4: 47.918464 | L4: 29.577507 | M4: 21.820759
A5: T_C_Conv_Ammonia_CCGT | B5: market for gas power plant, combined cycle, 400MW electrical | C5: gas power plant, combined cycle, 400MW electrical | D5: kgCO2eq/kW | E5: GLO | F5: 150.31334 | G5: 134.0643 | H5: 104.15643 | I5: 81.927221 | J5: 150.30541 | K5: 133.59069 | L5: 99.517999 | M5: 72.892403
A6: T_C_Conv_Ammonia_HaberBosch | B6: ammonia synthesis catalyst production | C6: ammonia synthesis catalyst | D6: kgCO2eq/kg | E6: GLO | F6: 0.000127 | G6: 9e-05 | H6: 4.2e-05 | I6: 3.1e-05 | J6: 0.000127 | K6: 9.3e-05 | L6: 4.1e-05 | M6: 2.7e-05
A7: T_C_Conv_Ammonia_OCGT | B7: micro gas turbine production, 100kW electrical | C7: micro gas turbine, 100kW electrical | D7: kgCO2eq/kW | E7: CH | F7: 147.72442 | G7: 122.83063 | H7: 92.419966 | I7: 78.201541 | J7: 147.71588 | K7: 121.58915 | L7: 85.641046 | M7: 62.633809
A8: T_C_Conv_CarbonCapture_Amine | B8: market for monoethanolamine | C8: monoethanolamine | D8: kgCO2eq/kg | E8: GLO | F8: 0.004459 | G8: 0.004009 | H8: 0.00342 | I8: 0.00316 | J8: 0.004459 | K8: 0.004016 | L8: 0.003404 | M8: 0.003121
A9: T_C_Conv_CarbonCapture_DacAbs | B9: direct air capture system, solvent-based, 1MtCO2 | C9: direct air capture system | D9: kgCO2eq/kg | E9: RER | F9: 0.007578 | G9: 0.006763 | H9: 0.005611 | I9: 0.004653 | J9: 0.007577 | K9: 0.006763 | L9: 0.005468 | M9: 0.004061
A10: T_C_Conv_CarbonCapture_DacAds | B10: direct air capture system, sorbent-based, 100ktCO2 | C10: direct air capture system | D10: kgCO2eq/kg | E10: RER | F10: 0.005743 | G10: 0.005003 | H10: 0.003832 | I10: 0.003016 | J10: 0.005743 | K10: 0.00498 | L10: 0.003655 | M10: 0.002608
A11: T_C_Conv_CarbonCapture_Hpc | B11: potassium carbonate production, from potassium hydroxide | C11: potassium carbonate | D11: kgCO2eq/kg | E11: GLO | F11: 0.001517 | G11: 0.001096 | H11: 0.000544 | I11: 0.000348 | J11: 0.001517 | K11: 0.001113 | L11: 0.00049 | M11: 0.000277
A12: T_C_Conv_CarbonMonoxide_Rwgs_H2_CO | B12: RWGS tank construction | C12: RWGS tank construction | D12: kgCO2eq/kg | E12: GLO | F12: 0.006293 | G12: 0.005231 | H12: 0.003517 | I12: 0.002569 | J12: 0.006293 | K12: 0.005251 | L12: 0.00314 | M12: 0.002094
A13: T_C_Conv_CatalyticHydropyrolysis_syngas | B13: chemical factory construction, organics | C13: chemical factory, organics | D13: kgCO2eq/kg | E13: RER | F13: 0.040275 | G13: 0.031371 | H13: 0.022305 | I13: 0.018086 | J13: 0.040271 | K13: 0.030886 | L13: 0.020787 | M13: 0.01612
A14: T_C_Conv_Coelectrolysis | B14: electrolyzer production, 1MWe, SOEC, BoP / Stack | C14: electrolyzer, 1MWe, SOEC, Stack | D14: kgCO2eq/kW | E14: RER | F14: 285.98691 | G14: 211.77497 | H14: 146.96989 | I14: 112.83659 | J14: 285.97094 | K14: 206.90486 | L14: 130.78391 | M14: 95.18833
A15: T_C_Conv_EL3_RWG | B15: RWGS tank construction | C15: RWGS tank construction | D15: kgCO2eq/kg | E15: GLO | F15: 0.006293 | G15: 0.005231 | H15: 0.003517 | I15: 0.002569 | J15: 0.006293 | K15: 0.005251 | L15: 0.00314 | M15: 0.002094
... A76: T_C_Sol_Solar_Pv_Roof_SolFlat | B76: photovoltaic flat-roof installation, 3kWp, multi-Si, on roof | C76: photovoltaic flat-roof installation, 3kWp, multi-Si, on roof | D76: kgCO2eq/kW | E76: CH | F76: 1273.5988 | G76: 938.12588 | H76: 529.67294 | I76: 400.06301 | J76: 1273.5568 | K76: 944.30206 | L76: 508.46186 | M76: 376.99505
A77: T_C_Conv_Pyrolysis_BioWet_CBio
A78: T_C_Conv_Pyrolysis_Wood_CBio
A79: T_C_Net_Elec_El47_ElRest_2020

Sheet Reference ID
A1: Reference ID | B1: Reference Description | C1: Reference Type | D1: DOI or Link | E1: Access Date | F1: PDF in server
A2: source_id | D2: doi_or_url
A3: report_VSE_2022 | B3: VSE Energiezukunft 2050, Studie 2022 | C3: BibTex | D3: https://www.strom.ch/de/energiezukunft-2050/download | E3: 45175 | F3: TRUE
A4: assumption_Empa_2022 | B4: Expert Assumption | C4: Assumption | D4: na | F4: TRUE
A5: paper_mutschler_2018 | C5: DOI | D5: https://doi.org/10.1016/j.jcat.2018.08.002 | F5: TRUE
A6: assumption_reFuelWP3_2025 | B6: Expert Assumption | C6: Assumption | D6: na | F6: TRUE
A7: report_VSE_2025 | B7: VSE Energiezukunft 2050, Update 2025 | C7: BibTex | D7: https://www.strom.ch/de/energiezukunft-2050/download | E7: 45803 | F7: TRUE
A8: paper_müller_PowerX_2025 | B8: The costs of future energy technologies: A comprehensive review of power-to-X processes | C8: DOI | D8: https://doi.org/10.1016/j.jcou.2025.103019 | F8: TRUE
A9: assumption_Empa_2025 | B9: Expert assumptions and calculations by Empa | C9: Assumption | D9: na | F9: TRUE
A10: paper_alpinePV_2024 | B10: ETHZ paper on Alpine PV cost and financial viability | C10: DOI | D10: https://doi.org/10.1016/j.apenergy.2024.124019 | F10: TRUE
A11: paper_PVcostProjection_2025 | B11: review the cost projection of PV, wind, battery | C11: DOI | D11: https://doi.org/10.1016/j.apenergy.2025.125856 | F11: TRUE
A12: assumption_PVcostProjection | B12: 4/3/2% cost reduction per year in 2030/2040/2050, see ref_id "paper_PVcostProjection_2025" | D12: na | F12: TRUE
A13: assumption_Empa_PV_OM | B13: currently FOM is 15-25 CHF/kW.year, may reduce to 10 in 2050 | D13: na | F13: TRUE
A14: web_BatteryCH_2023 | B14: article about market price of home batteries in CH, in 2023 | C14: BibTex | D14: https://alpvolt.com/en/news/solar-batteries-in-switzerland | F14: TRUE
A15: assumption_Empa_battery_capex_2025 | B15: assumption based on various info | D15: na | F15: TRUE
A16: web_Battery_OM_2025 | B16: FOM costs are estimated at 2.5% of the capital costs | C16: BibTex | D16: https://atb.nrel.gov/electricity/2024/utility-scale_battery_storage | F16: TRUE
A17: Allgoewer_2024 | B17: Paper by ETH from PATHFNDR | C17: DOI | D17: https://doi.org/10.1021/acs.iecr.4c01287 | F17: TRUE
A18: Rheintal_2025 | B18: Rheintal paper of Empa, submitted 2025 | C18: DOI | D18: https://dx.doi.org/10.2139/ssrn.5291581 | F18: TRUE
A19: book_hydropower_2020 | B19: Future Energy (Third Edition) | C19: DOI | D19: https://doi.org/10.1016/B978-0-08-102886-5.00015-3 | F19: TRUE
A20: report_danish_energy_2025 | B20: Report from Danish Energy Agency | D20: https://ens.dk/technologydata | E20: 45919 | F20: TRUE
A21: assumption_Empa_danish_energy_OE | B21: Overall Efficiency estimatin of biogas plants: Average(Efficiency values for different input carrieres) | D21: na | F21: TRUE
A22: paper_CCGT_2024 | B22: Modeling combined-cycle power plants in a detailed electricity market | C22: DOI | D22: https://doi.org/10.1016/j.energy.2024.131246 | F22: TRUE
A23: paper_CCGT+CCS_2016 | B23: Off-design point modelling of a 420 MW CCGT power plant integrated with an amine-based post-combustion CO2 capture and compression process | C23: DOI | D23: https://doi.org/10.1016/j.apenergy.2016.06.087 | F23: TRUE
A24: report_global_hydrogen_review_2024 | B24: he Global Hydrogen Review 2024 systematically monitors the global hydrogen sector, reporting that demand reached 97 Mt in 2023—mostly supplied by unabated fossil fuels—despite accelerating policy action, growing low-emissions project announcements, and almost USD 100 billion in public funding allocated to support the clean energy transition. | D24: https://iea.blob.core.windows.net/assets/89c1e382-dc59-46ca-aa47-9f7d41531ab5/GlobalHydrogenReview2024.pdf | F24: TRUE
A25: report_jrc_2021 | D25: https://doi.org/10.2760/527879 | F25: TRUE
A26: report_power_to_ammonia_2018 | B26: Power-to-ammonia in future North European 100 % renewable power and heat system | C26: DOI | D26: https://doi.org/10.1016/j.ijhydene.2018.06.121 | F26: TRUE
A27: conversion_parametrization | B27: Calculating Input Output Ratios of Reactions | D27: na
A28: paper_e-fuel production | B28: Forging a sustainable sky: Unveiling the pillars of aviation e-fuel production for carbon emission circularity | C28: DOI | D28: https://doi.org/10.1016/j.isci.2024.109154
A29: paper_wood to syngas | B29: Cutting-edge biomass gasification technologies for renewable energy generation and achieving net zero emissions | C29: DOI | D29: https://doi.org/10.1016/j.enconman.2024.119213
A30: report_wood to hydrogen | B30: Biomass gasification for hydrogen production | C30: URL | D30: https://www.ieabioenergy.com/wp-content/uploads/2025/03/IEA-Bioenergy_T33_Bio-H2_Final_v2.pdf
A31: paper_Msw to syngas | B31: Municipal Solid Waste Gasification: Technologies, Process Parameters, and Sustainable Valorization of By-Products in a Circular Economy | C31: DOI | D31: https://doi.org/10.3390/su17156704
A32: paper_RWGS | B32: Technology Readiness and Emerging Prospects of CoupledCatalytic Reactions for Sustainable Chemical Value Chains | C32: DOI | D32: https://doi.org/10.1002/cssc.202400865
A33: source_shares | B33: Temporary reference ID for input and output shares | D33: na
A34: paper_biogas | B34: Biogas-to-biomethane upgrading: A comparative review and assessment in a life cycle perspective | C34: DOI | D34: https://doi.org/10.1016/j.rser.2020.110588
A35: parameters_lca | B35: LCA Parameters
A36: assumption_
A37: Paper_Postcom_2021 | B37: Postcombustion CO2 Capture: A Comparative Techno-Economic Assessment of Three Technologies Using a Solvent, an Adsorbent, and a Membrane | D37: Postcombustion CO2 Capture: A Comparative Techno-Economic Assessment of Three Technologies Using a Solvent, an Adsorbent, and a Membrane | ACS Engineering Au
A38: AECOM_2022 | B38: AECOM 2022: Next Generation Carbon Capture Technology Technoeconomic Analysis Work Package 6
A39: biochar_jcp_2025 | B39: Financial feasibility of biochar production: A comparative analysis of business scenarios | C39: DOI | D39: https://doi.org/10.1016/j.jclepro.2025.147167
A40: EP2050+Exkurs | B40: Energieperspektiven 2050+ Exkurs Negativemissionstechnologien und CCS Potenziale, Kosten und Einsatz | C40: Link | D40: https://www.bfe.admin.ch/bfe/en/home/politik/energieperspektiven-2050-plus.exturl.html/aHR0cHM6Ly9wdWJkYi5iZmUuYWRtaW4uY2gvZGUvcHVibGljYX/Rpb24vZG93bmxvYWQvMTA2MjA=.html
...

Sheet SolarTech
A1: Review | E1: Classification | N1: Attributes | T1: Conversion Parameterization | AG1: Economic Parameterization | AO1: Uncertainty | AQ1: CO2 emissions | AU1: References
A2: [boolean] | B2: [Author] | C2: [Author] | D2: [boolean] | E2: [ehubX Tech ID] | F2: [Ontology IRI] | G2: [ProcessType] | H2: [Description] | I2: [MainSector] | J2: [MainCategory] | K2: [CategorySpec] | L2: [TechType] | M2: kW | N2: [Year] | O2: [Location] | P2: [Currency] | Q2: Year | R2: [TechMaturity] | S2: [TechBoundary] | T2: [boolean] | U2: [float] | V2: [float] | W2: [list of Carriers] | X2: [Carrier] | Y2: [list of floats, comma separated] | Z2: [list of units in kWh and kg] | AA2: [list of Carriers] | AB2: [Carrier] | AC2: [list of float, comma separated] | AD2: [list of units, comma separated] | AE2: kW | AF2: [float] | AG2: Years | AH2: Currency | AI2: Currency/kW | AJ2: Currency/year | AK2: % | AL2: Currency/kW/Year | AM2: Currency/kWh/Year | AN2: [float] | AO2: [boolean] | AP2: [str] | AQ2: [LCA ID] | AR2: [LCA Unit] | AS2: [Embedded Carbon] | AT2: [LCA Scenario] | AU2: [dict of ReferenceID]
A3: Review done | B3: 1st Review responsible | C3: 2nd Review responsible | D3: Review approved (Robin) | E3: ehubX Tech ID | F3: Tech Ontology IRI | G3: Process Type | H3: Description | I3: Main Sector | J3: Main Category | K3: Category Specification | L3: Tech Type | M3: Reference Unit Size | N3: Technology Year | O3: Cost Base | P3: Currency | Q3: Data Reference Year | R3: Technology Maturity Evaluation | S3: Technology Boundary | T3: Tech drawing added? | U3: Overall Efficiency | V3: Input, Output for Overall Efficiency | W3: Input Carriers | X3: Main Input Carrier | Y3: Input Shares | Z3: Input Units | AA3: Output Carriers | AB3: Main Output Carrier | AC3: Output Shares | AD3: Output Unit | AE3: Minimum Installation | AF3: Maximum Curtailment Fraction | AG3: Economic Lifetime | AH3: CAPEX One Time | AI3: CAPEX Power Capacity | AJ3: OPEX One Time | AK3: OPEX Power Capacity as Percentage of CAPEX | AL3: OPEX Power Capacity | AM3: OPEX Energy | AN3: Discount Rate | AO3: Value Range Check | AP3: Uncertainty Rating | AQ3: LCA ID | AR3: LCA Unit | AS3: Embedded Carbon | AT3: LCA Scenario | AU3: References
A4: TRUE | B4: Barton | C4: Gianfranco | D4: FALSE | E4: T_C_Sol_Solar_Pv_Roof_2025_SolFlat | H4: rooftop PV, small scale, in 2025 | I4: Electricity | J4: New Renewable | K4: PV | L4: Conversion | N4: 2025 | O4: CH | P4: CHF | Q4: 2022 | R4: Mature | T4: FALSE | V4: 1 | W4: SolFlat | Y4: 1 | AA4: ElBdg | AB4: ElBdg | AC4: 0.21 | AE4: 0 | AF4: 1 | AG4: 25 | AH4: 0 | AI4: 2647 | AJ4: 0 | AK4: 0.015 | AL4: 41 | AM4: 0 | AN4: 0.05 | AO4: FALSE | AU4: "CAPEX", "Opex Power Capacity": report_VSE_2025; "Output Shares": paper_alpinePV_2024; | AV4: Check source
A5: TRUE | B5: Barton | C5: Gianfranco | D5: FALSE | E5: T_C_Sol_Solar_Pv_Roof_2030_SolFlat | H5: rooftop PV, small scale, in 2030 | I5: Electricity | J5: New Renewable | K5: PV | L5: Conversion | N5: 2030 | O5: CH | P5: CHF | Q5: 2022 | R5: Mature | T5: FALSE | V5: 1 | W5: SolFlat | Y5: 1 | AA5: ElBdg | AB5: ElBdg | AC5: 0.23 | AE5: 0 | AF5: 1 | AG5: 25 | AH5: 0 | AI5: 1880 | AJ5: 0 | AK5: 0.0175 | AL5: =AI5*AK5 -> 32.9 | AM5: 0 | AN5: 0.05 | AO5: FALSE | AU5: "CAPEX", "Opex Power Capacity": report_VSE_2025; "Output Shares": paper_alpinePV_2024;
